Workbook

Sheet Quotation
B1: ASG LOGISTICS JOINT STOCK COMPANY
B2: Lot No. 5, Yen Binh industrial Zone, Van Xuan ward, Thai Nguyen province, Viet Nam
A3: QUOTATION
A4: Customer: Samsung SDS Vietnam Co., Ltd
A5: Address: Lot CN05, YP6 Road, Yenphong Industrial zone, YenTrung Commute, Bacninh
A6: OVERSIZED CARGO DESCRIPTION
A7: B/L NO:
A8: Cargo Name: CNC Main
A9: wooden pallets / tons / cbm
A10: Estimated Dimension after packing into wooden case:
A11: No. | B11: Services | C11: Chargeable | D11: Unit Price (Vnd) | E11: Remarkable
A12: 1 | B12: Net weight less than 5 ton
A13: 1.1 | B13: Wooden box less than 1 CBM
B14: Min rate | C14: VND/box | D14: 900000
A15: 1.2 | B15: Wooden box More than 1 CBM Less than 10 CBM
B16: Rate | C16: VND/CBM | D16: 900000
A17: 1.3 | B17: Wooden box more than 10 CBM
B18: Rate | C18: VND/CBM | D18: 1078000
A19: 2 | B19: Wooden box - Net weight from 5-10 ton
B20: Rate | C20: VND/CBM | D20: 1323000
A21: 3 | B21: Wooden box - Net weight from 10-15 ton
B22: Rate | C22: VND/CBM | D22: 1470000
A23: 4 | B23: Wooden box - Net weight from 15-20 ton
B24: Rate | C24: VND/CBM | D24: 1764000
A25: 5 | B25: Wooden box - Net weight from 20-30 ton
B26: Rate | C26: VND/CBM | D26: 2254000
A27: 6 | B27: Other cases | C27: Case by case
A28: 7 | B28: Air Vacuum packing
B29: Less than 8 CBM shipment | C29: VND/CBM | D29: 735000
B30: Over 8 CBM shipment | C30: VND/CBM | D30: 665000
A31: 8 | B31: Storage charge | C31: VND/block/7 days | D31: 20000
A32: 9 | B32: Trucking from SEVT -ASGL
B33: Rate | C33: VND/kg | D33: 180
B34: Min truck | C34: VND/Truck | D34: 750000
B35: Flat Bed truck | C35: VND/Truck | D35: 4500000
A36: 10 | B36: Fumigation fee
B37: 01*20 DC | C37: VND/ Cont | D37: 660000
B38: 01*40 DC | C38: VND/ Cont | D38: 880000
B39: LCL | C39: USD/ Cont | D39: 18
A40: 11 | B40: Unloading at ASGL
...

Sheet Quotation gỗ 10mm
A1: ASG LOGISTICS JOINT STOCK COMPANY
A2: Lot No. 5, Yen Binh industrial Zone, Van Xuan ward,Thai Nguyen province, Viet Nam
A3: QUOTATION
A4: Customer: Samsung SDS GSCL Viet Nam Co., Ltd
A5: Address: Lot CN05 - YP6 Street - Yen Phong Industrial Zone - Long Chau Community - Bac Ninh Province
A6: OVERSIZED CARGO DESCRIPTION
A7: B/L NO:
A8: Cargo Name: CNC Main
A9: wooden pallets / tons / cbm
A10: Estimated Dimension after packing into wooden case:
A11: No. | B11: Services | C11: Chargeable | D11: Unit Price (Vnd) | E11: Remarkable
A12: 1 | B12: Net weight less than 5 ton
A13: 1.1 | B13: Wooden box less than 1 CBM
B14: Min rate | C14: VND/box | D14: 990000 | E14: Thickness of plywood 10mm or more
A15: 1.2 | B15: Wooden box More than 1 CBM Less than 10 CBM
B16: Rate | C16: VND/CBM | D16: 990000 | E16: Thickness of plywood 10mm or more
A17: 1.3 | B17: Wooden box more than 10 CBM
B18: Rate | C18: VND/CBM | D18: 1185800 | E18: Thickness of plywood 10mm or more
A19: 2 | B19: Wooden box - Net weight from 5-10 ton
B20: Rate | C20: VND/CBM | D20: 1455300 | E20: Thickness of plywood 10mm or more
A21: 3 | B21: Wooden box - Net weight from 10-15 ton
B22: Rate | C22: VND/CBM | D22: 1617000 | E22: Thickness of plywood 10mm or more
A23: 4 | B23: Wooden box - Net weight from 15-20 ton
B24: Rate | C24: VND/CBM | D24: 1940400 | E24: Thickness of plywood 10mm or more
A25: 5 | B25: Wooden box - Net weight from 20-30 ton
B26: Rate | C26: VND/CBM | D26: 2479400 | E26: Thickness of plywood 10mm or more
C29: On behalf of ASG Logistics Company
C37: ĐẶNG NGỌC QUANG

Sheet Debit
B1: ASG LOGISTICS JOINT STOCK COMPANY
B2: Lot No. 5, Yen Binh industrial Zone, Van Xuan ward, Thai Nguyen province, Viet Nam
B3: Tax code: 4 6 0 1 1 2 6 8 8 6
A5: DEBIT NOTE
A6: Date: 09.01.2026
A7: Customer's name: TDI
A8: Address: Lot CN05, YP6 Road, Yenphong Industrial zone, YenTrung Commute, Bacninh
A9: Tax code: 2 3 0 0 6 8 0 9 9 1
A11: No. | B11: Asset Name | C11: Note | D11: Plt | E11: N.W | F11: G.W | G11: CBM/Pallet | H11: M2/pallet | I11: Out ASGL | J11: Truck No. | K11: Storage days | L11: Air Vacuum packing service (Contracted) | M11: Wooden Packing service (Contracted) | N11: Storage charge (Contracted) | O11: Unloading at ASGL (NonContracted) | P11: Loading at ASGL (NonContracted) | Q11: Management fee (Contracted) | R11: Trucking SEV-ASGL (NonContracted) | S11: Fumigation fee (Contracted) | T11: Canvas covering (just roof) | U11: Electrostatic vinyl
A12: 1 | B12: =Estimate!B4 -> 1500064205 | C12: =+Estimate!C4 -> Set Camera Tester | D12: =Estimate!H4 -> 1 | E12: =Estimate!G4 -> 140 | F12: =Estimate!P4 -> 140 | G12: =Estimate!O4 -> 2.16 | H12: =Estimate!L4*Estimate!M4 -> 1.2 | L12: =Estimate!AC4 -> 1436400 | M12: =Estimate!U4 -> 1944000 | N12: =20000*D12 -> 20000 | O12: =250*F12 -> 35000 | P12: =250*F12 -> 35000 | Q12: =40000*D12 -> 40000 | R12: 750000 | S12: =660000*1 -> 660000 | T12: =Estimate!AE4 -> 78000 | U12: =Estimate!AG4 -> 324000
A13: 2 | B13: =Estimate!B5 -> 1500067875 | C13: =+Estimate!C5 -> Set Camera Tester | D13: =Estimate!H5 -> 1 | E13: =Estimate!G5 -> 140 | F13: =Estimate!P5 -> 140 | G13: =Estimate!O5 -> 2.16 | H13: =Estimate!L5*Estimate!M5 -> 1.2 | L13: =Estimate!AC5 -> 1436400 | M13: =Estimate!U5 -> 1944000 | N13: =20000*D13 -> 20000 | O13: =250*F13 -> 35000 | P13: =250*F13 -> 35000 | Q13: =40000*D13 -> 40000 | T13: =Estimate!AE5 -> 78000 | U13: =Estimate!AG5 -> 324000
A14: 3 | B14: =Estimate!B6 -> 1500063106 | C14: =+Estimate!C6 -> Set Camera Tester | D14: =Estimate!H6 -> 1 | E14: =Estimate!G6 -> 140 | F14: =Estimate!P6 -> 140 | G14: =Estimate!O6 -> 2.16 | H14: =Estimate!L6*Estimate!M6 -> 1.2 | L14: =Estimate!AC6 -> 1436400 | M14: =Estimate!U6 -> 1944000 | N14: =20000*D14 -> 20000 | O14: =250*F14 -> 35000 | P14: =250*F14 -> 35000 | Q14: =40000*D14 -> 40000 | T14: =Estimate!AE6 -> 78000 | U14: =Estimate!AG6 -> 324000
A15: 4 | B15: =Estimate!B7 -> 1500063105 | C15: =+Estimate!C7 -> Set Camera Tester | D15: =Estimate!H7 -> 1 | E15: =Estimate!G7 -> 140 | F15: =Estimate!P7 -> 140 | G15: =Estimate!O7 -> 2.16 | H15: =Estimate!L7*Estimate!M7 -> 1.2 | L15: =Estimate!AC7 -> 1436400 | M15: =Estimate!U7 -> 1944000 | N15: =20000*D15 -> 20000 | O15: =250*F15 -> 35000 | P15: =250*F15 -> 35000 | Q15: =40000*D15 -> 40000 | T15: =Estimate!AE7 -> 78000 | U15: =Estimate!AG7 -> 324000
A16: Total | D16: =SUM(D12:D15) -> 4 | E16: =SUM(E12:E15) -> 560 | F16: =SUM(F12:F15) -> 560 | G16: =SUM(G12:G15) -> 8.64 | H16: =SUM(H12:H15) -> 4.8 | I16: =SUM(I12:I15) -> 0 | J16: =SUM(J12:J15) -> 0 | K16: =SUM(K12:K15) -> 0 | ... U16: =SUM(U12:U15) -> 1296000
A17: Total amount: | F17: =SUM(L16:S16) -> 15451600 | I17: (excluded VAT 10%)
J21: Tạm tính 1 Cont 20'

Sheet Estimate
K1: Đơn vị: mét
A2: STT | B2: Asset No | C2: Name | D2: Trước khi bọc | H2: số lượng | J2: Thể tích (1pc) | K2: Tống thể tích (All pcs/m3) | L2: Tạm tính sau khi bọc | T2: Đóng thùng gỗ | V2: Chằng buộc | X2: Bọc Bạt (112m2) | Z2: Giám định | AB2: Hút chân không | AD2: Phủ bạt nóc | AF2: Vinyl tĩnh điện
A3: Stt | D3: Dài | E3: Rộng | F3: Cao | G3: Cân nặng | I3: Tổng NW | L3: Dài | M3: Rộng | N3: Cao | O3: Thể tích (1pc) | P3: Cân nặng (kg) | Q3: Số lượng | R3: Tổng GW | S3: Tống thể tích (All pcs/m3) | T3: Đơn giá | U3: Tổng phí | V3: Đơn giá | W3: Tổng phí | X3: Đơn giá | Y3: Tổng phí | Z3: Đơn giá | AA3: Tổng phí | AB3: Đơn giá | AC3: Tổng phí | AD3: Đơn giá | AE3: Tổng phí | AF3: Đơn giá | AG3: Tổng phí
A4: 1 | B4: 1500064205 | C4: Set Camera Tester | D4: 0.9 | E4: 0.7 | F4: 1.5 | G4: 140 | H4: 1 | I4: =G4*H4 -> 140 | J4: =D4*E4*F4 -> 0.945 | K4: =J4*H4 -> 0.945 | L4: =D4+0.3 -> 1.2 | M4: =E4+0.3 -> 1 | N4: =F4+0.3 -> 1.8 | O4: =L4*M4*N4 -> 2.16 | P4: 140 | Q4: =H4 -> 1 | R4: =P4*Q4 -> 140 | S4: =O4*Q4 -> 2.16 | T4: =900000 -> 900000 | U4: =S4*T4 -> 1944000 | W4: =#REF!*V4 -> #REF! | Y4: =U4*X4 -> 0 | AA4: =W4*Z4 -> #REF! | AB4: 665000 | AC4: =AB4*S4 -> 1436400 | AD4: 65000 | AE4: =+AD4*L4*M4 -> 78000 | AF4: 150000 | AG4: =AF4*O4 -> 324000
A5: 2 | B5: 1500067875 | C5: Set Camera Tester | D5: 0.9 | E5: 0.7 | F5: 1.5 | G5: 140 | H5: 1 | I5: =G5*H5 -> 140 | J5: =D5*E5*F5 -> 0.945 | K5: =J5*H5 -> 0.945 | L5: =D5+0.3 -> 1.2 | M5: =E5+0.3 -> 1 | N5: =F5+0.3 -> 1.8 | O5: =L5*M5*N5 -> 2.16 | P5: 140 | Q5: =H5 -> 1 | R5: =P5*Q5 -> 140 | S5: =O5*Q5 -> 2.16 | T5: =900000 -> 900000 | U5: =S5*T5 -> 1944000 | W5: =#REF!*V5 -> #REF! | Y5: =U5*X5 -> 0 | AA5: =W5*Z5 -> #REF! | AB5: 665000 | AC5: =AB5*S5 -> 1436400 | AD5: 65000 | AE5: =+AD5*L5*M5 -> 78000 | AF5: 150000 | AG5: =AF5*O5 -> 324000
A6: 3 | B6: 1500063106 | C6: Set Camera Tester | D6: 0.9 | E6: 0.7 | F6: 1.5 | G6: 140 | H6: 1 | I6: =G6*H6 -> 140 | J6: =D6*E6*F6 -> 0.945 | K6: =J6*H6 -> 0.945 | L6: =D6+0.3 -> 1.2 | M6: =E6+0.3 -> 1 | N6: =F6+0.3 -> 1.8 | O6: =L6*M6*N6 -> 2.16 | P6: 140 | Q6: =H6 -> 1 | R6: =P6*Q6 -> 140 | S6: =O6*Q6 -> 2.16 | T6: =900000 -> 900000 | U6: =S6*T6 -> 1944000 | W6: =#REF!*V6 -> #REF! | Y6: =U6*X6 -> 0 | AA6: =W6*Z6 -> #REF! | AB6: 665000 | AC6: =AB6*S6 -> 1436400 | AD6: 65000 | AE6: =+AD6*L6*M6 -> 78000 | AF6: 150000 | AG6: =AF6*O6 -> 324000
A7: 4 | B7: 1500063105 | C7: Set Camera Tester | D7: 0.9 | E7: 0.7 | F7: 1.5 | G7: 140 | H7: 1 | I7: =G7*H7 -> 140 | J7: =D7*E7*F7 -> 0.945 | K7: =J7*H7 -> 0.945 | L7: =D7+0.3 -> 1.2 | M7: =E7+0.3 -> 1 | N7: =F7+0.3 -> 1.8 | O7: =L7*M7*N7 -> 2.16 | P7: 140 | Q7: =H7 -> 1 | R7: =P7*Q7 -> 140 | S7: =O7*Q7 -> 2.16 | T7: =900000 -> 900000 | U7: =S7*T7 -> 1944000 | W7: =#REF!*V7 -> #REF! | Y7: =U7*X7 -> 0 | AA7: =W7*Z7 -> #REF! | AB7: 665000 | AC7: =AB7*S7 -> 1436400 | AD7: 65000 | AE7: =+AD7*L7*M7 -> 78000 | AF7: 150000 | AG7: =AF7*O7 -> 324000
B8: Tổng: | G8: =SUM(G4:G7) -> 560 | H8: =SUM(H4:H7) -> 4 | I8: =SUM(I4:I7) -> 560 | J8: =SUM(J4:J7) -> 3.78 | K8: =SUM(K4:K4) -> 0.945 | L8: =SUM(L4:L7) -> 4.8 | M8: =SUM(M4:M7) -> 4 | N8: =SUM(N4:N7) -> 7.2 | O8: =SUM(O4:O7) -> 8.64 | P8: =SUM(P4:P7) -> 560 | Q8: =SUM(Q4:Q7) -> 4 | R8: =SUM(R4:R7) -> 560 | S8: =SUM(S4:S7) -> 8.64 | U8: =SUM(U4:U7) -> 7776000 | V8: =SUM(V4:V4) -> 0 | W8: =SUM(W4:W4) -> #REF! | X8: =SUM(X4:X4) -> 0 | Y8: =SUM(Y4:Y4) -> 0 | Z8: =SUM(Z4:Z4) -> 0 | AA8: =SUM(AA4:AA4) -> #REF! | AC8: =SUM(AC4:AC7) -> 5745600 | AE8: =SUM(AE4:AE7) -> 312000 | AG8: =SUM(AG4:AG7) -> 1296000

Sheet Sheet1
A1: Malaysia
A2: 법인명 | B2: Asset No | D2: Asset Name | E2: Quantity | F2: Maker | G2: Model | H2: Serial No. | I2: 용도 | J2: Cost Center Name | K2: Acquisition date | L2: Acquisition value | M2: Net Book Value | N2: 길이 (dài) | O2: 너비(rộng) | P2: 높이 (cao) | Q2: 무게 (cân nặng)
M3: (12월말기준)
A4: SEVT | B4: 1500011975 | C4: SEMA(Malaysia) | D4: SAOI;MV-8DH | E4: 1 | F4: MIRTEC | G4: MV-8DH | H4: 17120215-1739 | I4: PBA의부품장착상태검사하는설비 | J4: SMD P | K4: 41851 | L4: 34,366.21 | M4: - | N4: 1.3 | O4: 1.05 | P4: 1.45 | Q4: 950
A5: SEVT | B5: 1500050301 | C5: SEMA(Malaysia) | D5: Screen printer_MOMENTUM+ | E5: 1 | F5: SPEEDLINE | G5: MOMENTUM + | H5: M100378 | I5: Screen printer | J5: Hansol - SMD P | K5: 42551 | L5: 52,785.65 | M5: - | N5: 1.3 | O5: 1.05 | P5: 1.45 | Q5: 950
A6: SEVT | B6: 1500065921 | C6: SEMA(Malaysia) | D6: M-AOI MV-8DH | E6: 1 | F6: MIRTEC | G6: MV-8DH | H6: 17120223-1773 | I6: PBA의부품장착상태검사하는설비 | J6: SMD P | K6: 43628 | L6: 15,027.03 | M6: 7,263.07 | N6: 1.3 | O6: 1.05 | P6: 1.45 | Q6: 950
A7: SEVT | B7: 1500065924 | C7: SEMA(Malaysia) | D7: M-AOI MV-8DH | E7: 1 | F7: MIRTEC | G7: MV-8DH | H7: 17120223-1765 | I7: PBA의부품장착상태검사하는설비 | J7: SMD P | K7: 43628 | L7: 15,740.27 | M7: 7,607.84 | N7: 1.3 | O7: 1.05 | P7: 1.45 | Q7: 950
A10: hàn quốc
A11: 법인명 | B11: Asset No | D11: Asset Name | E11: Quantity | F11: Maker | G11: Model | H11: Serial No. | I11: 용도 | J11: Cost Center Name | K11: Acquisition date | L11: Acquisition value | M11: Net Book Value | N11: 길이 (dài) | O11: 너비(rộng) | P11: 높이 (cao) | Q11: 무게 (cân nặng)
M12: (12월말기준)
A13: SEVT | B13: 1500011980 | C13: Gwangju(Korea) | D13: MAOI;MV-8DH | E13: 1 | F13: MIRTEC | G13: MV-8DH | H13: 17120215-1749 | I13: PBA의부품장착상태검사하는설비 | J13: SMD P | K13: 41851 | L13: 34,366.21 | M13: - | N13: 1.3 | O13: 1.05 | P13: 1.45 | Q13: 950
A14: SEVT | B14: 1500050872 | C14: Gwangju(Korea) | D14: MAOI MV-8SH+ | E14: 1 | F14: MIRTEC | G14: MV-8SH+ | H14: 17100930-1070 | I14: PBA의부품장착상태검사하는설비 | J14: SMD P | K14: 42582 | L14: 257,065.42 | M14: - | N14: 1.3 | O14: 1.05 | P14: 1.45 | Q14: 950
A15: SEVT | B15: 1500051071 | C15: Gwangju(Korea) | D15: MAOI_MV-8SH+ | E15: 1 | F15: MIRTEC | G15: MV-8SH+ | H15: 17100918-1058 | I15: PBA의부품장착상태검사하는설비 | J15: SMD P | K15: 42582 | L15: 7,014.94 | M15: - | N15: 1.65 | O15: 1.27 | P15: 1.84 | Q15: 862
A16: SEVT | B16: 1500065933 | C16: Gwangju(Korea) | D16: S-AOI MV-8DH | E16: 1 | F16: MIRTEC | G16: MV-8DH | H16: 17120223-1781 | I16: PBA의부품장착상태검사하는설비 | J16: SMD P | K16: 43628 | L16: 9,805.88 | M16: 4,739.51 | N16: 1.4 | O16: 1.3 | P16: 1.5 | Q16: 950
A17: SEVT | B17: 1500065934 | C17: Gwangju(Korea) | D17: S-AOI MV-8DH | E17: 1 | F17: MIRTEC | G17: MV-8DH | H17: 17120223-1779 | I17: PBA의부품장착상태검사하는설비 | J17: SMD P | K17: 43628 | L17: 9,805.88 | M17: 4,739.51 | N17: 1.4 | O17: 1.3 | P17: 1.5 | Q17: 950
A18: SEVT | B18: 1500065939 | C18: Gwangju(Korea) | D18: S-AOI MV-8DH | E18: 1 | F18: MIRTEC | G18: MV-8DH | H18: 17120223-1782 | I18: PBA의부품장착상태검사하는설비 | J18: SMD P | K18: 43628 | L18: 18,449.79 | M18: 8,917.43 | N18: 1.3 | O18: 1.05 | P18: 1.45 | Q18: 950

Sheet container
B6: cbm | D6: daif | E6: rong | F6: cao
A7: cont 20" | B7: 28 | C7: 28 tan | D7: 5.898 | E7: 2.34 | F7: 2.395
A8: cont 40DC | B8: 60 | C8: 26 tan | D8: 12.032 | E8: 2.35 | F8: 2.392
A9: cont 40HC | B9: 68 | C9: 26 tan | D9: 12.032 | E9: 2.35 | F9: 2.698
